Workbook

Sheet Summary
B2: Tasks | C2: 1 | D2: 2 | E2: 3 | F2: 4 | G2: 5 | I2: Points Overview | J2: Points | K2: State Medal Point Requirement
B3: Fire Crystals | C3: Y | D3: Y | G3: Y | I3: Day 1 | J3: ='Day 1'!E2 -> 0 | K3: 200000
B4: Fire Crystal shards (Research) | C4: Y | D4: Y | G4: Y | I4: Day 2 | J4: ='Day 2'!E2 -> 0 | K4: 270000
B5: Refined Fire Crystals (FC6+) | C5: Y | D5: Y | G5: Y | I5: Day 3 | J5: ='Day 3'!E2 -> 0 | K5: 300000
B6: Lucky Wheel | D6: Y | E6: Y | I6: Day 4 | J6: ='Day 4'!E2 -> 0 | K6: 300000
B7: Hero Shards | D7: Y | E7: Y | I7: Day 5 | J7: ='Day 5'!E2 -> 0 | K7: Unsure, will update soon
B8: Widgets/Essence stones/Mithril | F8: Y | G8: Y | I8: Total SvS Score | J8: =SUM(J3:J7) -> 0 | K8: 250000 | L8: (Battle phase)
B9: Speedups | C9: Y | D9: Y | G9: Y
B10: Train troops | F10: Y
B11: Charms | C11: Y | E11: Y | F11: Y | I11: Only edit Green boxes
B12: Chief Gear | G12: Y | I12: Yellow boxes are subtotals/totals
B13: Gather resources | D13: Y
B14: Pet Advancement/Refine | E14: Y | G14: Y
B15: Polar Terror/Hunt beasts | E15: Y
B16: Experts-Sigil/Books | D16: Y | E16: Y
B17: Items in RED are the popular choices typically for that day, this is also dependant on the schedule of the state wide buffs offered. | K17: Updated as of 25/08/2025

Sheet Day 1
D2: Total points | E2: =SUM(E4:E8) -> 0
B3: Day 1 | D3: Materials | E3: Points
B4: Fire Crystals | C4: 2000 | E4: =D4*C4 -> 0
B5: Fire Crystal shards (Research) | C5: 1000 | E5: =D5*C5 -> 0
B6: Refined Fire Crystals (FC6+) | C6: 30000 | E6: =D6*C6 -> 0
B7: Speedups (1minute) | C7: 30 | D7: Fill in below | E7: =E14 -> 0
B8: Charms | C8: 70 | D8: Fill in below | E8: =E28 -> 0
B10: Speedups
B11: Days | C11: =24*60*30 -> 43200 | E11: =C11*D11 -> 0
B12: Hours | C12: =60*30 -> 1800 | E12: =C12*D12 -> 0
B13: Minutes | C13: =30 -> 30 | E13: =C13*D13 -> 0
E14: =SUM(E11:E13) -> 0
B16: Charms Level | C16: Points | D16: Pieces | E16: Points
B17: 1 | C17: 625 | E17: =C17*D17*70 -> 0
B18: 2 | C18: 1250 | E18: =C18*D18*70 -> 0
B19: 3 | C19: 3125 | E19: =C19*D19*70 -> 0
B20: 4 | C20: 8750 | E20: =C20*D20*70 -> 0
B21: 5 | C21: 11250 | E21: =C21*D21*70 -> 0
B22: 6 | C22: 12500 | E22: =C22*D22*70 -> 0
B23: 7 | C23: 12500 | E23: =C23*D23*70 -> 0
B24: 8 | C24: 13000 | E24: =C24*D24*70 -> 0
B25: 9 | C25: 14000 | E25: =C25*D25*70 -> 0
B26: 10 | C26: 15000 | E26: =C26*D26*70 -> 0
B27: 11 | C27: 16000 | E27: =C27*D27*70 -> 0
E28: =SUM(E17:E27) -> 0

Sheet Day 2
D2: Total points | E2: =SUM(E4:E11) -> 0
B3: Day 2 | D3: Materials | E3: Points
B4: Fire Crystals | C4: 2000 | E4: =D4*C4 -> 0
B5: Fire Crystal shards (Research) | C5: 1000 | E5: =D5*C5 -> 0
B6: Refined Fire Crystals (FC6+) | C6: 30000 | E6: =D6*C6 -> 0
B7: Lucky Wheel | C7: 8000 | E7: =D7*C7 -> 0
B8: Hero Shards | C8: Various | D8: Fill in below | E8: =E17 -> 0
B9: Speedups (1minute) | C9: 30 | D9: Fill in below | E9: =E22 -> 0
B10: Gather resources | C10: 2 | D10: Fill in below | E10: =E32 -> 0
B11: Experts-Sigils/books | C11: Various | D11: Fill in below | E11: =E38 -> 0
B13: Hero Shards | D13: Pieces | E13: Points
B14: Rare | C14: 350 | E14: =D14*C14 -> 0
B15: Epic | C15: 1220 | E15: =D15*C15 -> 0
B16: Mythic | C16: 3040 | E16: =D16*C16 -> 0
E17: =SUM(E14:E16) -> 0
B18: Speedups
B19: Days | C19: =24*60*30 -> 43200 | E19: =C19*D19 -> 0
B20: Hours | C20: =60*30 -> 1800 | E20: =C20*D20 -> 0
B21: Minutes | C21: =30 -> 30 | E21: =C21*D21 -> 0
E22: =SUM(E19:E21) -> 0
B24: Gather resources | D24: Number | E24: Points
B25: T8 (Meat, Wood, Coal. Iron) | C25: 28000 | E25: =C25*D25 -> 0
B26: T7 | C26: 12000 | E26: =C26*D26 -> 0
B27: T6 | C27: 6000 | E27: =C27*D27 -> 0
B28: T5 | C28: 2400 | E28: =C28*D28 -> 0
B29: T4 | C29: 1200 | E29: =C29*D29 -> 0
B30: T3 | C30: 600 | E30: =C30*D30 -> 0
B31: T2 | C31: 300 | E31: =C31*D31 -> 0
B32: T1 | C32: 140 | E32: =C32*D32 -> 0
E33: =SUM(E25:E32) -> 0
B35: Experts
B36: Sigils | C36: 6000 | E36: =C36*D36 -> 0
B37: Books of Knowledge | C37: 60 | E37: =C37*D37 -> 0
E38: =SUM(E36:E37) -> 0

Sheet Day 3
E2: =SUM(E4:E11) -> 0
B3: Day 3 | D3: Materials | E3: Points | G3: Beasts | I3: Number | J3: Points
B4: Lucky Wheel | C4: 8000 | E4: =D4*C4 -> 0 | G4: Level 1-10 | H4: 9000 | J4: =I4*H4 -> 0
B5: Hero Shards | C5: Various | D5: Fill in below | E5: =E17 -> 0 | G5: Level 11-15 | H5: 9750 | J5: =I5*H5 -> 0
B6: Charms | C6: 70 | D6: Fill in below | E6: =E37 -> 0 | G6: Level 16-20 | H6: 10500 | J6: =I6*H6 -> 0
B7: Pet Advancement | C7: 50 | D7: Fill in below | E7: =J32 -> 0 | G7: Level 21-25 | H7: 11250 | J7: =I7*H7 -> 0
B8: Pet Refine | C8: Various | D8: Fill in below | E8: =J38 -> 0 | G8: Level 26-30 | H8: 12000 | J8: =I8*H8 -> 0
B9: Hunting Beasts | C9: Various | D9: Fill in below | E9: =J9 -> 0 | J9: =SUM(J4:J8) -> 0
B10: Polar terrors | C10: 30000 | D10: Fill in below | E10: =L18 -> 0 | J10: Gina:No Gina | K10: Rallies | L10: Points | M10: Enter "1"
B11: Experts-Sigils/books | C11: Various | D11: Fill in below | E11: =E42 -> 0 | G11: Polar terrors | J11: 1:0 (Gina Only) | K11: =H16/20 -> 0 | L11: =K11*30000 -> 0 | N11: =M11*L11 -> 0
G12: Level 1-6 | H12: 30000 | J12: 1:1 | K12: =H16/((20+25)/2) -> 0 | L12: =K12*30000 -> 0 | N12: =M12*L12 -> 0
B13: Hero Shards | D13: Pieces | E13: Points | G13: Stamina Calculator | J13: 1:2 | K13: =H16/((20+50)/3) -> 0 | L13: =K13*30000 -> 0 | N13: =M13*L13 -> 0
B14: Rare | C14: 350 | E14: =D14*C14 -> 0 | G14: Starting Stamina | J14: 1:3 | K14: =H16/((20+75)/4) -> 0 | L14: =K14*30000 -> 0 | N14: =M14*L14 -> 0
B15: Epic | C15: 1220 | E15: =D15*C15 -> 0 | G15: Chief Stamina (inside bag) | J15: 1:4 | K15: =H16/((20+100)/5) -> 0 | L15: =K15*30000 -> 0 | N15: =M15*L15 -> 0
B16: Mythic | C16: 3040 | E16: =D16*C16 -> 0 | G16: Total Stamina | H16: =H14+H15*10 -> 0 | J16: 1:5 | K16: =H16/((20+125)/6) -> 0 | L16: =K16*30000 -> 0 | N16: =M16*L16 -> 0
E17: =SUM(E14:E16) -> 0 | J17: 0:6 (No Gina) | K17: =H16/25 -> 0 | L17: =K17*30000 -> 0 | N17: =M17*L17 -> 0
L18: =SUM(N11:N17) -> 0
L19: How to use Stamina Calculator:
B20: Charms Level | C20: Points | D20: Pieces | E20: Points | L20: 1) Enter starting Stamina and Chief stamina in bag on left
B21: 1 | C21: 625 | E21: =C21*D21*70 -> 0 | G21: Pet advancement | I21: Number | J21: Points | L21: 2) Pick Ratio of Gina vs Non Gina waves sent (if you have 6 marchs for example and want to continuous send all marches out, then select 1:5 ratio.
B22: 2 | C22: 1250 | E22: =C22*D22*70 -> 0 | G22: Level 10 | H22: 500 | J22: =H22*I22*50 -> 0
B23: 3 | C23: 3125 | E23: =C23*D23*70 -> 0 | G23: Level 20 | H23: 1000 | J23: =H23*I23*50 -> 0
B24: 4 | C24: 8750 | E24: =C24*D24*70 -> 0 | G24: Level 30 | H24: 2000 | J24: =H24*I24*50 -> 0 | L24: 3) Put a "1" in the green column corresponding to the ratio row to automatically generate the score to add in your daily total. Eg put a "1" in Cell M16 for 1:5 ratio.
B25: 5 | C25: 11250 | E25: =C25*D25*70 -> 0 | G25: Level 40 | H25: 3000 | J25: =H25*I25*50 -> 0
B26: 6 | C26: 12500 | E26: =C26*D26*70 -> 0 | G26: Level 50 | H26: 4500 | J26: =H26*I26*50 -> 0
B27: 7 | C27: 12500 | E27: =C27*D27*70 -> 0 | G27: Level 60 | H27: 6750 | J27: =H27*I27*50 -> 0
B28: 8 | C28: 13000 | E28: =C28*D28*70 -> 0 | G28: Level 70 | H28: 10000 | J28: =H28*I28*50 -> 0
B29: 9 | C29: 14000 | E29: =C29*D29*70 -> 0 | G29: Level 80 | H29: 12000 | J29: =H29*I29*50 -> 0
B30: 10 | C30: 15000 | E30: =C30*D30*70 -> 0 | G30: Level 90 | H30: 14500 | J30: =H30*I30*50 -> 0
B31: 11 | C31: 16000 | E31: =C31*D31*70 -> 0 | G31: Level 100 | H31: 17500 | J31: =H31*I31*50 -> 0
B32: 12 | C32: 17000 | E32: =C32*D32*70 -> 0 | J32: =SUM(J22:J31) -> 0
B33: 13 | C33: 18000 | E33: =C33*D33*70 -> 0
B34: 14 | C34: 19000 | E34: =C34*D34*70 -> 0
B35: 15 | C35: 20000 | E35: =C35*D35*70 -> 0 | G35: Pet Refining | I35: Pieces | J35: Points
B36: 16 | C36: 21000 | E36: =C36*D36*70 -> 0 | G36: Common Wild Marks | H36: 1150 | J36: =I36*H36 -> 0
E37: =SUM(E21:E36) -> 0 | G37: Advanced Wild Marks | H37: 15000 | J37: =I37*H37 -> 0
J38: =SUM(J36:J37) -> 0
B39: Experts
B40: Sigils | C40: 6000 | E40: =C40*D40 -> 0
B41: Books of Knowledge | C41: 60 | E41: =C41*D41 -> 0
...

Sheet Day 4
E2: =SUM(E4:E8) -> 0
B3: Day 4 | D3: Materials | E3: Points
B4: Widgets | C4: 8000 | E4: =D4*C4 -> 0
B5: Essence Stones | C5: 4000 | E5: =D5*C5 -> 0
B6: Mithril | C6: 144000 | E6: =D6*C6 -> 0
B7: Charms | C7: 70 | D7: Fill in below | E7: =J27 -> 0
B8: Train troops | C8: T1-11 | D8: Fill in below | E8: =E22 -> 0
B10: Troops | D10: Number | E10: Points | G10: Charms Level | H10: Points | I10: Pieces | J10: Points
B11: T1 | C11: 3 | E11: =C11*D11 -> 0 | G11: 1 | H11: 625 | J11: =H11*I11*70 -> 0
B12: T2 | C12: 4 | E12: =C12*D12 -> 0 | G12: 2 | H12: 1250 | J12: =H12*I12*70 -> 0
B13: T3 | C13: 5 | E13: =C13*D13 -> 0 | G13: 3 | H13: 3125 | J13: =H13*I13*70 -> 0
B14: T4 | C14: 8 | E14: =C14*D14 -> 0 | G14: 4 | H14: 8750 | J14: =H14*I14*70 -> 0
B15: T5 | C15: 12 | E15: =C15*D15 -> 0 | G15: 5 | H15: 11250 | J15: =H15*I15*70 -> 0
B16: T6 | C16: 18 | E16: =C16*D16 -> 0 | G16: 6 | H16: 12500 | J16: =H16*I16*70 -> 0
B17: T7 | C17: 25 | E17: =C17*D17 -> 0 | G17: 7 | H17: 12500 | J17: =H17*I17*70 -> 0
B18: T8 | C18: 35 | E18: =C18*D18 -> 0 | G18: 8 | H18: 13000 | J18: =H18*I18*70 -> 0
B19: T9 | C19: 45 | E19: =C19*D19 -> 0 | G19: 9 | H19: 14000 | J19: =H19*I19*70 -> 0
B20: T10 | C20: 60 | E20: =C20*D20 -> 0 | G20: 10 | H20: 15000 | J20: =H20*I20*70 -> 0
B21: T11 | C21: 75 | E21: =C21*D21 -> 0 | G21: 11 | H21: 16000 | J21: =H21*I21*70 -> 0
E22: =SUM(E11:E21) -> 0 | G22: 12 | H22: 17000 | J22: =H22*I22*70 -> 0
G23: 13 | H23: 18000 | J23: =H23*I23*70 -> 0
G24: 14 | H24: 19000 | J24: =H24*I24*70 -> 0
G25: 15 | H25: 20000 | J25: =H25*I25*70 -> 0
G26: 16 | H26: 21000 | J26: =H26*I26*70 -> 0
J27: =SUM(J11:J26) -> 0

Sheet Day 5
D2: Total points | E2: =SUM(E4:E13) -> 0
B3: Day 5 | D3: Materials | E3: Points
B4: Fire Crystals | C4: 2000 | E4: =D4*C4 -> 0
B5: Fire Crystal shards (Research) | C5: 1000 | E5: =D5*C5 -> 0
B6: Refined Fire Crystals (FC6+) | C6: 30000 | E6: =D6*C6 -> 0
B7: Widgets | C7: 8000 | E7: =D7*C7 -> 0
B8: Essence Stones | C8: 4000 | E8: =D8*C8 -> 0
B9: Mithril | C9: 144000 | E9: =D9*C9 -> 0
B10: Speedups (1minute) | C10: 30 | D10: Fill in below | E10: =E19 -> 0
B11: Chief Gear | C11: 36 | D11: Fill in below | E11: =E39 -> 0
B12: Pet Advancement | C12: 50 | D12: Fill in below | E12: =J26 -> 0
B13: Pet Refine | C13: Various | D13: Fill in below | E13: =J31 -> 0
B15: Speedups | G15: Pet advancement | I15: Number | J15: Points
B16: Days | C16: =24*60*30 -> 43200 | E16: =C16*D16 -> 0 | G16: Level 10 | H16: 500 | J16: =H16*I16*50 -> 0
B17: Hours | C17: =60*30 -> 1800 | E17: =C17*D17 -> 0 | G17: Level 20 | H17: 1000 | J17: =H17*I17*50 -> 0
B18: Minutes | C18: =30 -> 30 | E18: =C18*D18 -> 0 | G18: Level 30 | H18: 2000 | J18: =H18*I18*50 -> 0
E19: =SUM(E16:E18) -> 0 | G19: Level 40 | H19: 3000 | J19: =H19*I19*50 -> 0
G20: Level 50 | H20: 4500 | J20: =H20*I20*50 -> 0
G21: Level 60 | H21: 6750 | J21: =H21*I21*50 -> 0
B22: Chief Gear | C22: Points | D22: Pieces | E22: Points | G22: Level 70 | H22: 10000 | J22: =H22*I22*50 -> 0
B23: Uncommon | C23: 1125 | E23: =C23*D23*36 -> 0 | G23: Level 80 | H23: 12000 | J23: =H23*I23*50 -> 0
B24: Uncommon 1* | C24: 1875 | E24: =C24*D24*36 -> 0 | G24: Level 90 | H24: 14500 | J24: =H24*I24*50 -> 0
B25: Rare | C25: 3000 | E25: =C25*D25*36 -> 0 | G25: Level 100 | H25: 17500 | J25: =H25*I25*50 -> 0
B26: Rare 1* | C26: 4500 | E26: =C26*D26*36 -> 0 | J26: =SUM(J16:J25) -> 0
B27: Rare 2* | C27: 5100 | E27: =C27*D27*36 -> 0
B28: Rare 3* | C28: 5440 | E28: =C28*D28*36 -> 0 | G28: Pet Refining | I28: Pieces | J28: Points
B29: Epic | C29: 3230 | E29: =C29*D29*36 -> 0 | G29: Common Wild Marks | H29: 1150 | J29: =I29*H29 -> 0
B30: Epic 1* | C30: 3230 | E30: =C30*D30*36 -> 0 | G30: Advanced Wild Marks | H30: 15000 | J30: =I30*H30 -> 0
B31: Epic 2* | C31: 3225 | E31: =C31*D31*36 -> 0 | J31: =SUM(J29:J30) -> 0
B32: Epic 3* | C32: 3225 | E32: =C32*D32*36 -> 0
B33: Epic T1 | C33: 3440 | E33: =C33*D33*36 -> 0
B34: Epic T1 1* | C34: 3440 | E34: =C34*D34*36 -> 0
B35: Epic T1 2* | C35: 4085 | E35: =C35*D35*36 -> 0
B36: Epic T1 3* | C36: 4085 | E36: =C36*D36*36 -> 0
B37: Mythic (all level) | C37: 6250 | E37: =C37*D37*36 -> 0
B38: Legendary (all level) | C38: 9560 | E38: =C38*D38*36 -> 0
E39: =SUM(E23:E38) -> 0
